Workbook

Sheet PARAMETER
A1: PARAMETER | B1: CHILE | C1: PERU | D1: ECUADOR | E1: COLOMBIA | F1: BOLIVIA
A2: Retail Sales | B2: Retail GDV | C2: Retail | D2: RETAIL | E2: RETAIL | F2: Ventas
A3: Wholesales | B3: Wholesale | C3: Wholesale | D3: WHOLESALE | E3: WHOLESALE | F3: Wholesale GM
A4: Registration | B4: Patentes | C4: Matrículas | D4: MATRICULAS | E4: RETAIL | F4: Ventas
A5: Day Supply Dealer Stock | B5: Day Supply Dealer Stock | C5: DOH Dealer | D5: DIAS RED
A6: Day Supply PS Available | B6: Day Supply PS Available | C6: DOH GM | D6: DIAS PLANTA
A7: Days of Sales
A8: Dealer Stock | B8: Dealer Stock | C8: Inv. Final Dealer | D8: INV RED | E8: STOCK DEALER
A9: Market Share | B9: Market Share | C9: MS% | D9: MS
A10: Mix (% of Country) | B10: Mix (% of Country)
A11: Plant Stock Available | B11: Plant Stock | C11: Inv. Final GM | D11: INV PLANTA | E11: STOCK GM | F11: Stock Final
A12: Plant Stock not Available
A13: Plant Stock Total
A14: Production | B14: Producción | E14: PRODUCCIÓN | F14: Producción
A15: Transit | B15: Embarques | E15: TRANSITO | F15: Pedido
A16: Arrivals | B16: Llegadas | C16: Llegadas | D16: PRODUCCION | E16: LLEGADAS | F16: Llegadas RT Bolivia

Sheet SEGMENT
A1: NAMEPLATE | B1: SEGMENT
A2: 310C | B2: CAR-B
A3: 310C NB | B3: CAR-B
A4: BEAT | B4: CAR-A
A5: BLAZER | B5: SUV-D
A6: BLAZER EV | B6: SUV-D
A7: BOLT | B7: SUV-B
A8: BOLT EUV | B8: SUV-B
A9: CADILLAC | B9: CADILLAC
A10: CAMARO | B10: SPORT
A11: CAPTIVA | B11: SUV-C
A12: CAPTIVA NEV | B12: SUV-C
... A59: CAPTIVA PHEV | B59: SUV-C

Sheet CHILE
A1: NAMEPLATE | B1: TRIM | C1: SEGMENT | D1: CONCAT | E1: NAMEPLATE COUNTRY | F1: TRIM 1 | G1: TRIM 2 | H1: TRIM 3
A2: BLAZER | B2: RS AT | C2: =_xlfn.XLOOKUP(A2,SEGMENT!A:A,SEGMENT!B:B) -> SUV-D | D2: =_xlfn.CONCAT(A2," ",B2) -> BLAZER RS AT | E2: BLAZER | F2: RS AT | G2: PROTOTIPO
A3: BLAZER | B3: OBSOLETO | C3: =_xlfn.XLOOKUP(A3,SEGMENT!A:A,SEGMENT!B:B) -> SUV-D | D3: =_xlfn.CONCAT(A3," ",B3) -> BLAZER OBSOLETO | E3: BLAZER | F3: OBSOLETA
A4: BLAZER EV | B4: RS AT | C4: =_xlfn.XLOOKUP(A4,SEGMENT!A:A,SEGMENT!B:B) -> SUV-D | D4: =_xlfn.CONCAT(A4," ",B4) -> BLAZER EV RS AT | E4: BLAZER EV | F4: PROTOTIPO | G4: RS | H4: BLAZER EV
A5: BOLT EUV | B5: LT AT | C5: =_xlfn.XLOOKUP(A5,SEGMENT!A:A,SEGMENT!B:B) -> SUV-B | D5: =_xlfn.CONCAT(A5," ",B5) -> BOLT EUV LT AT | E5: BOLT | F5: PROTOTIPO | G5: LT
A6: CADILLAC | B6: CADILLAC | C6: =_xlfn.XLOOKUP(A6,SEGMENT!A:A,SEGMENT!B:B) -> CADILLAC | D6: =_xlfn.CONCAT(A6," ",B6) -> CADILLAC CADILLAC | E6: LYRIQ | F6: LYRIQ
A7: CADILLAC | B7: CADILLAC | C7: =_xlfn.XLOOKUP(A7,SEGMENT!A:A,SEGMENT!B:B) -> CADILLAC | D7: =_xlfn.CONCAT(A7," ",B7) -> CADILLAC CADILLAC | E7: VISTIQ | F7: VISTIQ
A8: CAMARO | B8: CAMARO | C8: =_xlfn.XLOOKUP(A8,SEGMENT!A:A,SEGMENT!B:B) -> SPORT | D8: =_xlfn.CONCAT(A8," ",B8) -> CAMARO CAMARO | E8: CAMARO | F8: 6.2L SS AT RWD
A9: CAPTIVA | B9: PREMIER MT | C9: =_xlfn.XLOOKUP(A9,SEGMENT!A:A,SEGMENT!B:B) -> SUV-C | D9: =_xlfn.CONCAT(A9," ",B9) -> CAPTIVA PREMIER MT | E9: NEW CAPTIVA | F9: PREMIER MT
A10: CAPTIVA | B10: PREMIER AT | C10: =_xlfn.XLOOKUP(A10,SEGMENT!A:A,SEGMENT!B:B) -> SUV-C | D10: =_xlfn.CONCAT(A10," ",B10) -> CAPTIVA PREMIER AT | E10: NEW CAPTIVA | F10: PREMIER CVT
A11: CAPTIVA | B11: LTZ MT | C11: =_xlfn.XLOOKUP(A11,SEGMENT!A:A,SEGMENT!B:B) -> SUV-C | D11: =_xlfn.CONCAT(A11," ",B11) -> CAPTIVA LTZ MT | E11: NEW CAPTIVA | F11: LTZ MT
A12: CAPTIVA | B12: LTZ AT | C12: =_xlfn.XLOOKUP(A12,SEGMENT!A:A,SEGMENT!B:B) -> SUV-C | D12: =_xlfn.CONCAT(A12," ",B12) -> CAPTIVA LTZ AT | E12: NEW CAPTIVA | F12: PROTOTIPO | G12: LTZ CVT
A13: CAPTIVA | B13: OBSOLETO | C13: =_xlfn.XLOOKUP(A13,SEGMENT!A:A,SEGMENT!B:B) -> SUV-C | D13: =_xlfn.CONCAT(A13," ",B13) -> CAPTIVA OBSOLETO | E13: NEW CAPTIVA | F13: OBSOLETA
A14: CAPTIVA | B14: OBSOLETO | C14: =_xlfn.XLOOKUP(A14,SEGMENT!A:A,SEGMENT!B:B) -> SUV-C | D14: =_xlfn.CONCAT(A14," ",B14) -> CAPTIVA OBSOLETO | E14: CAPTIVA | F14: OBSOLETA
A15: CAPTIVA NEV | B15: PHEV | C15: =_xlfn.XLOOKUP(A15,SEGMENT!A:A,SEGMENT!B:B) -> SUV-C | D15: =_xlfn.CONCAT(A15," ",B15) -> CAPTIVA NEV PHEV | E15: F510S | F15: PHEV LI | G15: PHEV | H15: HV
A16: CAPTIVA NEV | B16: EUV | C16: =_xlfn.XLOOKUP(A16,SEGMENT!A:A,SEGMENT!B:B) -> SUV-C | D16: =_xlfn.CONCAT(A16," ",B16) -> CAPTIVA NEV EUV | E16: F510S | F16: EV LI | G16: EV | H16: PROTOTIPO
A17: COLORADO | B17: OBSOLETO | C17: =_xlfn.XLOOKUP(A17,SEGMENT!A:A,SEGMENT!B:B) -> PICKUP-D | D17: =_xlfn.CONCAT(A17," ",B17) -> COLORADO OBSOLETO | E17: COLORADO | F17: OBSOLETA
A18: COLORADO | B18: Z71 AT | C18: =_xlfn.XLOOKUP(A18,SEGMENT!A:A,SEGMENT!B:B) -> PICKUP-D | D18: =_xlfn.CONCAT(A18," ",B18) -> COLORADO Z71 AT | E18: COLORADO | F18: Z71
A19: COLORADO | B19: WT MT 4X4 | C19: =_xlfn.XLOOKUP(A19,SEGMENT!A:A,SEGMENT!B:B) -> PICKUP-D | D19: =_xlfn.CONCAT(A19," ",B19) -> COLORADO WT MT 4X4 | E19: COLORADO | F19: LT MT 4x4 | G19: WT MT 4x4
A20: COLORADO | B20: WT MT 4X2 | C20: =_xlfn.XLOOKUP(A20,SEGMENT!A:A,SEGMENT!B:B) -> PICKUP-D | D20: =_xlfn.CONCAT(A20," ",B20) -> COLORADO WT MT 4X2 | E20: COLORADO | F20: LT MT 4x2 | G20: WT MT 4x2
A21: COLORADO | B21: WT AT | C21: =_xlfn.XLOOKUP(A21,SEGMENT!A:A,SEGMENT!B:B) -> PICKUP-D | D21: =_xlfn.CONCAT(A21," ",B21) -> COLORADO WT AT | E21: COLORADO | F21: LT AT 4x4 | G21: WT AT 4x4
A22: COLORADO | B22: LTZ MT | C22: =_xlfn.XLOOKUP(A22,SEGMENT!A:A,SEGMENT!B:B) -> PICKUP-D | D22: =_xlfn.CONCAT(A22," ",B22) -> COLORADO LTZ MT | E22: COLORADO | F22: LTZ MT
A23: COLORADO | B23: LTZ AT | C23: =_xlfn.XLOOKUP(A23,SEGMENT!A:A,SEGMENT!B:B) -> PICKUP-D | D23: =_xlfn.CONCAT(A23," ",B23) -> COLORADO LTZ AT | E23: COLORADO | F23: LTZ AT
A24: COLORADO | B24: HC AT | C24: =_xlfn.XLOOKUP(A24,SEGMENT!A:A,SEGMENT!B:B) -> PICKUP-D | D24: =_xlfn.CONCAT(A24," ",B24) -> COLORADO HC AT | E24: COLORADO | F24: HC | G24: PROTOTIPO
A25: D-MAX | B25: OBSOLETO | C25: =_xlfn.XLOOKUP(A25,SEGMENT!A:A,SEGMENT!B:B) -> PICKUP-D | D25: =_xlfn.CONCAT(A25," ",B25) -> D-MAX OBSOLETO | E25: D-MAX | F25: OBSOLETA
A26: EQUINOX | B26: RS AT | C26: =_xlfn.XLOOKUP(A26,SEGMENT!A:A,SEGMENT!B:B) -> SUV-C | D26: =_xlfn.CONCAT(A26," ",B26) -> EQUINOX RS AT | E26: EQUINOX | F26: PROTOTIPO | G26: PREMIER CVT
A27: EQUINOX | B27: OBSOLETO | C27: =_xlfn.XLOOKUP(A27,SEGMENT!A:A,SEGMENT!B:B) -> SUV-C | D27: =_xlfn.CONCAT(A27," ",B27) -> EQUINOX OBSOLETO | E27: EQUINOX | F27: OBSOLETA
A28: EQUINOX EV | B28: LT AT | C28: =_xlfn.XLOOKUP(A28,SEGMENT!A:A,SEGMENT!B:B) -> SUV-C | D28: =_xlfn.CONCAT(A28," ",B28) -> EQUINOX EV LT AT | E28: EQUINOX EV | F28: EQUINOX EV | G28: RS | H28: LTZ
A29: EQUINOX EV | B29: LT AT | C29: =_xlfn.XLOOKUP(A29,SEGMENT!A:A,SEGMENT!B:B) -> SUV-C | D29: =_xlfn.CONCAT(A29," ",B29) -> EQUINOX EV LT AT | E29: EQUINOX EV | F29: PROTOTIPO
A30: GMICA | B30: OBSOLETO | C30: =_xlfn.XLOOKUP(A30,SEGMENT!A:A,SEGMENT!B:B) -> B&T | D30: =_xlfn.CONCAT(A30," ",B30) -> GMICA OBSOLETO | E30: FRR | F30: OBSOLETA
A31: GMICA | B31: OBSOLETO | C31: =_xlfn.XLOOKUP(A31,SEGMENT!A:A,SEGMENT!B:B) -> B&T | D31: =_xlfn.CONCAT(A31," ",B31) -> GMICA OBSOLETO | E31: FTR | F31: OBSOLETA
A32: GMICA | B32: OBSOLETO | C32: =_xlfn.XLOOKUP(A32,SEGMENT!A:A,SEGMENT!B:B) -> B&T | D32: =_xlfn.CONCAT(A32," ",B32) -> GMICA OBSOLETO | E32: FVR | F32: OBSOLETA
A33: GMICA | B33: GMICA | C33: =_xlfn.XLOOKUP(A33,SEGMENT!A:A,SEGMENT!B:B) -> B&T | D33: =_xlfn.CONCAT(A33," ",B33) -> GMICA GMICA | E33: FRR | F33: 0 | G33: FRR
A34: GMICA | B34: GMICA | C34: =_xlfn.XLOOKUP(A34,SEGMENT!A:A,SEGMENT!B:B) -> B&T | D34: =_xlfn.CONCAT(A34," ",B34) -> GMICA GMICA | E34: FTR | F34: 0
A35: GMICA | B35: GMICA | C35: =_xlfn.XLOOKUP(A35,SEGMENT!A:A,SEGMENT!B:B) -> B&T | D35: =_xlfn.CONCAT(A35," ",B35) -> GMICA GMICA | E35: FVR | F35: 0 | G35: FVR
A36: GMICA | B36: GMICA | C36: =_xlfn.XLOOKUP(A36,SEGMENT!A:A,SEGMENT!B:B) -> B&T | D36: =_xlfn.CONCAT(A36," ",B36) -> GMICA GMICA | E36: NPR | F36: 0 | G36: NPR
A37: GMICA | B37: GMICA | C37: =_xlfn.XLOOKUP(A37,SEGMENT!A:A,SEGMENT!B:B) -> B&T | D37: =_xlfn.CONCAT(A37," ",B37) -> GMICA GMICA | E37: NPS | F37: 0 | G37: NPS
A38: GMICA | B38: GMICA | C38: =_xlfn.XLOOKUP(A38,SEGMENT!A:A,SEGMENT!B:B) -> B&T | D38: =_xlfn.CONCAT(A38," ",B38) -> GMICA GMICA | E38: NQR | F38: 0 | G38: NQR
A39: GMICA | B39: GMICA | C39: =_xlfn.XLOOKUP(A39,SEGMENT!A:A,SEGMENT!B:B) -> B&T | D39: =_xlfn.CONCAT(A39," ",B39) -> GMICA GMICA | E39: N-RD | F39: 0
A40: GMICA | B40: GMICA | C40: =_xlfn.XLOOKUP(A40,SEGMENT!A:A,SEGMENT!B:B) -> B&T | D40: =_xlfn.CONCAT(A40," ",B40) -> GMICA GMICA | E40: N-RS | F40: 0
...

Sheet PERU
A1: NAMEPLATE | B1: TRIM | C1: SEGMENT | D1: CONCAT | E1: NAMEPLATE COUNTRY | F1: TRIM 1 | G1: TRIM 2 | H1: TRIM 3
A2: SAIL | B2: OBSOLETO | C2: =_xlfn.XLOOKUP(A2,SEGMENT!A:A,SEGMENT!B:B) -> CAR-B | D2: =_xlfn.CONCAT(A2," ",B2) -> SAIL OBSOLETO | E2: 310C HB | F2: 310C HB LT MT | G2: 310C HB LTZ MT | H2: 310C HB LTZ CVT
A3: BEAT | B3: OBSOLETO | C3: =_xlfn.XLOOKUP(A3,SEGMENT!A:A,SEGMENT!B:B) -> CAR-A | D3: =_xlfn.CONCAT(A3," ",B3) -> BEAT OBSOLETO | E3: BEAT | F3: BEAT LT BASE | G3: BEAT LT BASE + AC | H3: BEAT LT FULL
A4: BOLT | B4: OBSOLETO | C4: =_xlfn.XLOOKUP(A4,SEGMENT!A:A,SEGMENT!B:B) -> SUV-B | D4: =_xlfn.CONCAT(A4," ",B4) -> BOLT OBSOLETO | E4: BOLT | F4: BOLT EUV
A5: CAMARO | B5: OBSOLETO | C5: =_xlfn.XLOOKUP(A5,SEGMENT!A:A,SEGMENT!B:B) -> SPORT | D5: =_xlfn.CONCAT(A5," ",B5) -> CAMARO OBSOLETO | E5: CAMARO | F5: CAMARO COUPÉ 6.2 V8 SS AT
A6: CAPTIVA | B6: LTZ AT | C6: =_xlfn.XLOOKUP(A6,SEGMENT!A:A,SEGMENT!B:B) -> SUV-C | D6: =_xlfn.CONCAT(A6," ",B6) -> CAPTIVA LTZ AT | E6: CN202S | F6: NEW CAPTIVA Lv.2 AT 5 PAX
A7: CAPTIVA | B7: LTZ MT | C7: =_xlfn.XLOOKUP(A7,SEGMENT!A:A,SEGMENT!B:B) -> SUV-C | D7: =_xlfn.CONCAT(A7," ",B7) -> CAPTIVA LTZ MT | E7: CN202S | F7: NEW CAPTIVA Lv.2 MT 5 PAX
A8: CAPTIVA | B8: PREMIER AT | C8: =_xlfn.XLOOKUP(A8,SEGMENT!A:A,SEGMENT!B:B) -> SUV-C | D8: =_xlfn.CONCAT(A8," ",B8) -> CAPTIVA PREMIER AT | E8: CN202S | F8: NEW CAPTIVA Lv.3 AT 7 PAX
A9: CAPTIVA | B9: PREMIER MT | C9: =_xlfn.XLOOKUP(A9,SEGMENT!A:A,SEGMENT!B:B) -> SUV-C | D9: =_xlfn.CONCAT(A9," ",B9) -> CAPTIVA PREMIER MT | E9: CN202S | F9: NEW CAPTIVA Lv.3 MT 7 PAX
A10: CAPTIVA | B10: OBSOLETO | C10: =_xlfn.XLOOKUP(A10,SEGMENT!A:A,SEGMENT!B:B) -> SUV-C | D10: =_xlfn.CONCAT(A10," ",B10) -> CAPTIVA OBSOLETO | E10: CAPTIVA | F10: CAPTIVA 2.4 LS MT 2WD | G10: CAPTIVA 2.4 LS AT 2WD | H10: CAPTIVA 2.4 LS MT 2WD FULL
A11: CAPTIVA | B11: OBSOLETO | C11: =_xlfn.XLOOKUP(A11,SEGMENT!A:A,SEGMENT!B:B) -> SUV-C | D11: =_xlfn.CONCAT(A11," ",B11) -> CAPTIVA OBSOLETO | E11: CAPTIVA | F11: CAPTIVA 2.4 LS AT 2WD FULL | G11: CAPTIVA 2.4 LT AT AWD FULL DELUXE
A12: CAPTIVA | B12: OBSOLETO | C12: =_xlfn.XLOOKUP(A12,SEGMENT!A:A,SEGMENT!B:B) -> SUV-C | D12: =_xlfn.CONCAT(A12," ",B12) -> CAPTIVA OBSOLETO | E12: CN100V | F12: CN100V 1.2 MT MOVE | G12: CN100V 1.2 MT MOVE AC
A13: CAPTIVA EV | B13: EV | C13: =_xlfn.XLOOKUP(A13,SEGMENT!A:A,SEGMENT!B:B) -> SUV-C | D13: =_xlfn.CONCAT(A13," ",B13) -> CAPTIVA EV EV | E13: F510S EV | F13: F510S EV
A14: CAPTIVA PHEV | B14: PHEV | C14: =_xlfn.XLOOKUP(A14,SEGMENT!A:A,SEGMENT!B:B) -> SUV-C | D14: =_xlfn.CONCAT(A14," ",B14) -> CAPTIVA PHEV PHEV | E14: F510S PHEV | F14: F510S PHEV
A15: CAPTIVA EV | B15: EV | C15: =_xlfn.XLOOKUP(A15,SEGMENT!A:A,SEGMENT!B:B) -> SUV-C | D15: =_xlfn.CONCAT(A15," ",B15) -> CAPTIVA EV EV | E15: F510S | F15: F510S EV
A16: CAPTIVA PHEV | B16: PHEV | C16: =_xlfn.XLOOKUP(A16,SEGMENT!A:A,SEGMENT!B:B) -> SUV-C | D16: =_xlfn.CONCAT(A16," ",B16) -> CAPTIVA PHEV PHEV | E16: F510S | F16: F510S PHEV
A17: CAVALIER | B17: OBSOLETO | C17: =_xlfn.XLOOKUP(A17,SEGMENT!A:A,SEGMENT!B:B) -> CAR-C | D17: =_xlfn.CONCAT(A17," ",B17) -> CAVALIER OBSOLETO | E17: K216 | F17: K216 1.5 LS MT | G17: K216 1.5 LT MT | H17: K216 1.5 LTZ AT
A18: COBALT | B18: OBSOLETO | C18: =_xlfn.XLOOKUP(A18,SEGMENT!A:A,SEGMENT!B:B) -> CAR-B | D18: =_xlfn.CONCAT(A18," ",B18) -> COBALT OBSOLETO | E18: COBALT | F18: COBALT 1.8 LTZ MT | G18: COBALT 1.8 LTZ AT
A19: COLORADO | B19: HC AT | C19: =_xlfn.XLOOKUP(A19,SEGMENT!A:A,SEGMENT!B:B) -> PICKUP-D | D19: =_xlfn.CONCAT(A19," ",B19) -> COLORADO HC AT | E19: S10 | F19: S10 CREW CAB 2.8 DIESEL HIGH COUNTRY AT
A20: COLORADO | B20: LTZ MT | C20: =_xlfn.XLOOKUP(A20,SEGMENT!A:A,SEGMENT!B:B) -> PICKUP-D | D20: =_xlfn.CONCAT(A20," ",B20) -> COLORADO LTZ MT | E20: S10 | F20: S10 CREW CAB 2.8 DIESEL 4 DR LTZ
A21: COLORADO | B21: WT AT | C21: =_xlfn.XLOOKUP(A21,SEGMENT!A:A,SEGMENT!B:B) -> PICKUP-D | D21: =_xlfn.CONCAT(A21," ",B21) -> COLORADO WT AT | E21: S10 | F21: S10 CREW CAB 2.8 DIESEL 4 DR LT
A22: COLORADO | B22: Z71 AT | C22: =_xlfn.XLOOKUP(A22,SEGMENT!A:A,SEGMENT!B:B) -> PICKUP-D | D22: =_xlfn.CONCAT(A22," ",B22) -> COLORADO Z71 AT | E22: S10 | F22: S10 CREW CAB 2.8 DIESEL 4 DR ZL1 AT
A23: COLORADO | B23: OBSOLETO | C23: =_xlfn.XLOOKUP(A23,SEGMENT!A:A,SEGMENT!B:B) -> PICKUP-D | D23: =_xlfn.CONCAT(A23," ",B23) -> COLORADO OBSOLETO | E23: S10 | F23: S10 2.8 LT MT 4WD | G23: S10 CREW CAB 2.8 DIESEL 4 DR LTZ-AT | H23: S10 2.8 LT MT 4WD ABS DAB
A24: COLORADO | B24: OBSOLETO | C24: =_xlfn.XLOOKUP(A24,SEGMENT!A:A,SEGMENT!B:B) -> PICKUP-D | D24: =_xlfn.CONCAT(A24," ",B24) -> COLORADO OBSOLETO | E24: S10 | F24: S10 2.8 LTZ AT 4WD FULL | G24: S10 2.8 LTZ MT 4WD FULL | H24: S10 3.6 LTZ AT 2WD
A25: COLORADO | B25: OBSOLETO | C25: =_xlfn.XLOOKUP(A25,SEGMENT!A:A,SEGMENT!B:B) -> PICKUP-D | D25: =_xlfn.CONCAT(A25," ",B25) -> COLORADO OBSOLETO | E25: S10 | F25: S10 3.6 LTZ AT 4WD FULL | G25: S10 3.6 LTZ AT 2WD FULL | H25: S10 CREW CAB 2.8 DIESEL 4 MIDNIGHT AT
A26: COLORADO | B26: OBSOLETO | C26: =_xlfn.XLOOKUP(A26,SEGMENT!A:A,SEGMENT!B:B) -> PICKUP-D | D26: =_xlfn.CONCAT(A26," ",B26) -> COLORADO OBSOLETO | E26: S10 | F26: S10 CREW CAB 2.8 DIESEL 4 DR LS | G26: S10 CREW CAB 2.8 DIESEL 4 DR LS 4x2
A27: CRUZE | B27: OBSOLETO | C27: =_xlfn.XLOOKUP(A27,SEGMENT!A:A,SEGMENT!B:B) -> CAR-C | D27: =_xlfn.CONCAT(A27," ",B27) -> CRUZE OBSOLETO | E27: CRUZE | F27: CRUZE SEDAN 1.8 LS MT FULL | G27: CRUZE SEDAN 1.8 LS AT PREMIUM
A28: CRUZE D2 | B28: OBSOLETO | C28: =_xlfn.XLOOKUP(A28,SEGMENT!A:A,SEGMENT!B:B) -> CAR-C | D28: =_xlfn.CONCAT(A28," ",B28) -> CRUZE D2 OBSOLETO | E28: CRUZE D2 | F28: CRUZE SEDAN 1.4T LT MT
A29: EQUINOX | B29: OBSOLETO | C29: =_xlfn.XLOOKUP(A29,SEGMENT!A:A,SEGMENT!B:B) -> SUV-C | D29: =_xlfn.CONCAT(A29," ",B29) -> EQUINOX OBSOLETO | E29: EQUINOX | F29: EQUINOX LT AT | G29: EQUINOX LTZ AT | H29: EQUINOX RS AT
A30: EQUINOX EV | B30: LT AT | C30: =_xlfn.XLOOKUP(A30,SEGMENT!A:A,SEGMENT!B:B) -> SUV-C | D30: =_xlfn.CONCAT(A30," ",B30) -> EQUINOX EV LT AT | E30: EQUINOX | F30: EQUINOX EV AT
A31: GROOVE | B31: LT MT | C31: =_xlfn.XLOOKUP(A31,SEGMENT!A:A,SEGMENT!B:B) -> SUV-B | D31: =_xlfn.CONCAT(A31," ",B31) -> GROOVE LT MT | E31: GROOVE | F31: GROOVE 1.5 LT MT
A32: GROOVE | B32: PREMIER MT | C32: =_xlfn.XLOOKUP(A32,SEGMENT!A:A,SEGMENT!B:B) -> SUV-B | D32: =_xlfn.CONCAT(A32," ",B32) -> GROOVE PREMIER MT | E32: GROOVE | F32: GROOVE 1.5 PREMIER MT
A33: GROOVE | B33: RS MT | C33: =_xlfn.XLOOKUP(A33,SEGMENT!A:A,SEGMENT!B:B) -> SUV-B | D33: =_xlfn.CONCAT(A33," ",B33) -> GROOVE RS MT | E33: GROOVE | F33: GROOVE 1.5 RS MT
A34: GROOVE | B34: RS AT | C34: =_xlfn.XLOOKUP(A34,SEGMENT!A:A,SEGMENT!B:B) -> SUV-B | D34: =_xlfn.CONCAT(A34," ",B34) -> GROOVE RS AT | E34: GROOVE | F34: GROOVE 1.5 RS CVT
A35: GROOVE | B35: OBSOLETO | C35: =_xlfn.XLOOKUP(A35,SEGMENT!A:A,SEGMENT!B:B) -> SUV-B | D35: =_xlfn.CONCAT(A35," ",B35) -> GROOVE OBSOLETO | E35: GROOVE | F35: GROOVE 1.5 PREMIER AT
A36: JOY | B36: OBSOLETO | C36: =_xlfn.XLOOKUP(A36,SEGMENT!A:A,SEGMENT!B:B) -> CAR-B | D36: =_xlfn.CONCAT(A36," ",B36) -> JOY OBSOLETO | E36: JOY | F36: JOY 1.4L MT
A37: JOY NB | B37: OBSOLETO | C37: =_xlfn.XLOOKUP(A37,SEGMENT!A:A,SEGMENT!B:B) -> CAR-B | D37: =_xlfn.CONCAT(A37," ",B37) -> JOY NB OBSOLETO | E37: JOY SEDAN | F37: JOY SEDAN 1.4L MT
A38: MONTANA | B38: PREMIER AT | C38: =_xlfn.XLOOKUP(A38,SEGMENT!A:A,SEGMENT!B:B) -> PICKUP-C | D38: =_xlfn.CONCAT(A38," ",B38) -> MONTANA PREMIER AT | E38: NEW MONTANA | F38: MONTANA 1.2T PR AT
A39: MONTANA | B39: PREMIER MT | C39: =_xlfn.XLOOKUP(A39,SEGMENT!A:A,SEGMENT!B:B) -> PICKUP-C | D39: =_xlfn.CONCAT(A39," ",B39) -> MONTANA PREMIER MT | E39: NEW MONTANA | F39: MONTANA 1.2T PR MT
A40: MONTANA | B40: RS AT | C40: =_xlfn.XLOOKUP(A40,SEGMENT!A:A,SEGMENT!B:B) -> PICKUP-C | D40: =_xlfn.CONCAT(A40," ",B40) -> MONTANA RS AT | E40: NEW MONTANA | F40: MONTANA 1.2T RS AT
...

Sheet ECUADOR
A1: NAMEPLATE | B1: TRIM | C1: SEGMENT | D1: CONCAT | E1: NAMEPLATE COUNTRY | F1: TRIM 1 | G1: TRIM 2 | H1: TRIM 3
A2: BLAZER EV | B2: RS AT | C2: =_xlfn.XLOOKUP(A2,SEGMENT!A:A,SEGMENT!B:B) -> SUV-D | D2: =_xlfn.CONCAT(A2," ",B2) -> BLAZER EV RS AT | E2: BLAZER | F2: BLAZER EV RS AWD
A3: BOLT EUV | B3: OBSOLETO | C3: =_xlfn.XLOOKUP(A3,SEGMENT!A:A,SEGMENT!B:B) -> SUV-B | D3: =_xlfn.CONCAT(A3," ",B3) -> BOLT EUV OBSOLETO | E3: BOLT | F3: BOLT EUV
A4: CAPTIVA | B4: LT MT | C4: =_xlfn.XLOOKUP(A4,SEGMENT!A:A,SEGMENT!B:B) -> SUV-C | D4: =_xlfn.CONCAT(A4," ",B4) -> CAPTIVA LT MT | E4: CAPTIVA | F4: Captiva LT TM
A5: CAPTIVA | B5: LT AT | C5: =_xlfn.XLOOKUP(A5,SEGMENT!A:A,SEGMENT!B:B) -> SUV-C | D5: =_xlfn.CONCAT(A5," ",B5) -> CAPTIVA LT AT | E5: CAPTIVA | F5: Captiva LT TA
A6: CAPTIVA | B6: PREMIER AT | C6: =_xlfn.XLOOKUP(A6,SEGMENT!A:A,SEGMENT!B:B) -> SUV-C | D6: =_xlfn.CONCAT(A6," ",B6) -> CAPTIVA PREMIER AT | E6: CAPTIVA | F6: Captiva TA 7 pax premier
A7: CAPTIVA | B7: PREMIER MT | C7: =_xlfn.XLOOKUP(A7,SEGMENT!A:A,SEGMENT!B:B) -> SUV-C | D7: =_xlfn.CONCAT(A7," ",B7) -> CAPTIVA PREMIER MT | E7: CAPTIVA | F7: Captiva TM 7 pax premier
A8: CAPTIVA NEV | B8: EUV | C8: =_xlfn.XLOOKUP(A8,SEGMENT!A:A,SEGMENT!B:B) -> SUV-C | D8: =_xlfn.CONCAT(A8," ",B8) -> CAPTIVA NEV EUV | E8: Captiva EV | F8: F510s
A9: CAPTIVA NEV | B9: PHEV | C9: =_xlfn.XLOOKUP(A9,SEGMENT!A:A,SEGMENT!B:B) -> SUV-C | D9: =_xlfn.CONCAT(A9," ",B9) -> CAPTIVA NEV PHEV | E9: Captiva PHEV | F9: F510s PHEV
A10: CAPTIVA NEV | B10: EUV | C10: =_xlfn.XLOOKUP(A10,SEGMENT!A:A,SEGMENT!B:B) -> SUV-C | D10: =_xlfn.CONCAT(A10," ",B10) -> CAPTIVA NEV EUV | E10: F510s | F10: F510s
A11: CAPTIVA NEV | B11: PHEV | C11: =_xlfn.XLOOKUP(A11,SEGMENT!A:A,SEGMENT!B:B) -> SUV-C | D11: =_xlfn.CONCAT(A11," ",B11) -> CAPTIVA NEV PHEV | E11: F510S | F11: F510s PHEV
A12: COLORADO | B12: OBSOLETO | C12: =_xlfn.XLOOKUP(A12,SEGMENT!A:A,SEGMENT!B:B) -> PICKUP-D | D12: =_xlfn.CONCAT(A12," ",B12) -> COLORADO OBSOLETO | E12: COLORADO | F12: Colorado LT TM
A13: COLORADO | B13: HC AT | C13: =_xlfn.XLOOKUP(A13,SEGMENT!A:A,SEGMENT!B:B) -> PICKUP-D | D13: =_xlfn.CONCAT(A13," ",B13) -> COLORADO HC AT | E13: COLORADO | F13: Colorado HC AT
... A30: GROOVE | B30: RS MT | C30: =_xlfn.XLOOKUP(A30,SEGMENT!A:A,SEGMENT!B:B) -> SUV-B | D30: =_xlfn.CONCAT(A30," ",B30) -> GROOVE RS MT | E30: NEW GROOVE | F30: NEW GROOVE RS AC 1.5 5P 4X2 TM
A31: JOY | B31: OBSOLETO | C31: =_xlfn.XLOOKUP(A31,SEGMENT!A:A,SEGMENT!B:B) -> CAR-B | D31: =_xlfn.CONCAT(A31," ",B31) -> JOY OBSOLETO | E31: JOY | F31: Joy HB BASE | G31: JOY HB BLACK | H31: JOY HB
A32: JOY NB | B32: OBSOLETO | C32: =_xlfn.XLOOKUP(A32,SEGMENT!A:A,SEGMENT!B:B) -> CAR-B | D32: =_xlfn.CONCAT(A32," ",B32) -> JOY NB OBSOLETO | E32: JOY PLUS | F32: JOY NB BLACK
A33: JOY NB | B33: OBSOLETO | C33: =_xlfn.XLOOKUP(A33,SEGMENT!A:A,SEGMENT!B:B) -> CAR-B | D33: =_xlfn.CONCAT(A33," ",B33) -> JOY NB OBSOLETO | E33: JOY PLUS | F33: JOY NB
A34: MONTANA | B34: PREMIER MT | C34: =_xlfn.XLOOKUP(A34,SEGMENT!A:A,SEGMENT!B:B) -> PICKUP-C | D34: =_xlfn.CONCAT(A34," ",B34) -> MONTANA PREMIER MT | E34: MONTANA | F34: MONTANA PREMIER TM
A35: MONTANA | B35: RS AT | C35: =_xlfn.XLOOKUP(A35,SEGMENT!A:A,SEGMENT!B:B) -> PICKUP-C | D35: =_xlfn.CONCAT(A35," ",B35) -> MONTANA RS AT | E35: MONTANA | F35: MONTANA RS TA
A36: N400 | B36: CARGO FULL | C36: =_xlfn.XLOOKUP(A36,SEGMENT!A:A,SEGMENT!B:B) -> VAN-B | D36: =_xlfn.CONCAT(A36," ",B36) -> N400 CARGO FULL | E36: N400 | F36: N400 CARGO
A37: N400 | B37: PASS FULL | C37: =_xlfn.XLOOKUP(A37,SEGMENT!A:A,SEGMENT!B:B) -> VAN-B | D37: =_xlfn.CONCAT(A37," ",B37) -> N400 PASS FULL | E37: N400 | F37: N400 PASAJEROS
A38: ONIX | B38: LTZ MT | C38: =_xlfn.XLOOKUP(A38,SEGMENT!A:A,SEGMENT!B:B) -> CAR-B | D38: =_xlfn.CONCAT(A38," ",B38) -> ONIX LTZ MT | E38: ONIX | F38: ONIX 1.4L LTZ MT
A39: ONIX | B39: LTZ AT | C39: =_xlfn.XLOOKUP(A39,SEGMENT!A:A,SEGMENT!B:B) -> CAR-B | D39: =_xlfn.CONCAT(A39," ",B39) -> ONIX LTZ AT | E39: ONIX | F39: ONIX 1.4L LTZ AT
A40: ONIX | B40: RS MT | C40: =_xlfn.XLOOKUP(A40,SEGMENT!A:A,SEGMENT!B:B) -> CAR-B | D40: =_xlfn.CONCAT(A40," ",B40) -> ONIX RS MT | E40: ONIX | F40: Onix HB Turbo RS MT
A41: ONIX | B41: OBSOLETO | C41: =_xlfn.XLOOKUP(A41,SEGMENT!A:A,SEGMENT!B:B) -> CAR-B | D41: =_xlfn.CONCAT(A41," ",B41) -> ONIX OBSOLETO | E41: ONIX | F41: ONIX HB LT | G41: ONIX 1.4L LT MT
A42: ONIX | B42: OBSOLETO | C42: =_xlfn.XLOOKUP(A42,SEGMENT!A:A,SEGMENT!B:B) -> CAR-B | D42: =_xlfn.CONCAT(A42," ",B42) -> ONIX OBSOLETO | E42: ONIX | F42: ONIX NB LT
A43: ONIX NB | B43: LTZ MT | C43: =_xlfn.XLOOKUP(A43,SEGMENT!A:A,SEGMENT!B:B) -> CAR-B | D43: =_xlfn.CONCAT(A43," ",B43) -> ONIX NB LTZ MT | E43: ONIX PLUS | F43: Onix NB Turbo LTZ MT
A44: ONIX NB | B44: PREMIER AT | C44: =_xlfn.XLOOKUP(A44,SEGMENT!A:A,SEGMENT!B:B) -> CAR-B | D44: =_xlfn.CONCAT(A44," ",B44) -> ONIX NB PREMIER AT | E44: ONIX PLUS | F44: Onix NB Turbo Premier AT
A45: OTHER | B45: OTHER | C45: =_xlfn.XLOOKUP(A45,SEGMENT!A:A,SEGMENT!B:B) -> OTROS | D45: =_xlfn.CONCAT(A45," ",B45) -> OTHER OTHER | E45: Other | F45: Other
A46: SAIL | B46: OBSOLETO | C46: =_xlfn.XLOOKUP(A46,SEGMENT!A:A,SEGMENT!B:B) -> CAR-B | D46: =_xlfn.CONCAT(A46," ",B46) -> SAIL OBSOLETO | E46: SAIL | F46: SAIL A/C | G46: SAIL STD
A47: SAIL | B47: PREMIER | C47: =_xlfn.XLOOKUP(A47,SEGMENT!A:A,SEGMENT!B:B) -> CAR-B | D47: =_xlfn.CONCAT(A47," ",B47) -> SAIL PREMIER | E47: SAIL | F47: SAIL HB PREMIER
A48: SAIL NB | B48: LT AT | C48: =_xlfn.XLOOKUP(A48,SEGMENT!A:A,SEGMENT!B:B) -> CAR-B | D48: =_xlfn.CONCAT(A48," ",B48) -> SAIL NB LT AT | E48: SAIL PLUS | F48: SAIL PLUS
A49: SILVERADO | B49: Z71 AT | C49: =_xlfn.XLOOKUP(A49,SEGMENT!A:A,SEGMENT!B:B) -> PICKUP-E | D49: =_xlfn.CONCAT(A49," ",B49) -> SILVERADO Z71 AT | E49: SILVERADO | F49: SILVERADO
A50: SPARK EUV | B50: EUV | C50: =_xlfn.XLOOKUP(A50,SEGMENT!A:A,SEGMENT!B:B) -> SUV-B | D50: =_xlfn.CONCAT(A50," ",B50) -> SPARK EUV EUV | E50: SPARK EUV | F50: SPARK EUV
A51: SUBURBAN | B51: Z71 AT | C51: =_xlfn.XLOOKUP(A51,SEGMENT!A:A,SEGMENT!B:B) -> SUV-E | D51: =_xlfn.CONCAT(A51," ",B51) -> SUBURBAN Z71 AT | E51: SUBURBAN | F51: SUBURBAN
A52: TAHOE | B52: Z71 AT | C52: =_xlfn.XLOOKUP(A52,SEGMENT!A:A,SEGMENT!B:B) -> SUV-E | D52: =_xlfn.CONCAT(A52," ",B52) -> TAHOE Z71 AT | E52: TAHOE | F52: TAHOE Z71 AC 5.3 5P 4x4 TA
A53: TRACKER | B53: LS AT | C53: =_xlfn.XLOOKUP(A53,SEGMENT!A:A,SEGMENT!B:B) -> SUV-B | D53: =_xlfn.CONCAT(A53," ",B53) -> TRACKER LS AT | E53: TRACKER | F53: TRACKER LT TURBO 1.2 TA
A54: TRACKER | B54: LS MT | C54: =_xlfn.XLOOKUP(A54,SEGMENT!A:A,SEGMENT!B:B) -> SUV-B | D54: =_xlfn.CONCAT(A54," ",B54) -> TRACKER LS MT | E54: TRACKER | F54: TRACKER LT TURBO 1.2 TM
A55: TRACKER | B55: LTZ AT | C55: =_xlfn.XLOOKUP(A55,SEGMENT!A:A,SEGMENT!B:B) -> SUV-B | D55: =_xlfn.CONCAT(A55," ",B55) -> TRACKER LTZ AT | E55: TRACKER | F55: TRACKER LTZ TURBO 1.2 TA
A56: TRACKER | B56: LTZ MT | C56: =_xlfn.XLOOKUP(A56,SEGMENT!A:A,SEGMENT!B:B) -> SUV-B | D56: =_xlfn.CONCAT(A56," ",B56) -> TRACKER LTZ MT | E56: TRACKER | F56: TRACKER LTZ TURBO MCM AT
...

Sheet COLOMBIA
A1: NAMEPLATE | B1: TRIM | C1: SEGMENT | D1: CONCAT | E1: NAMEPLATE COUNTRY | F1: TRIM 1 | G1: TRIM 2 | H1: TRIM 3
A2: BLAZER | B2: RS AT | C2: =_xlfn.XLOOKUP(A2,SEGMENT!A:A,SEGMENT!B:B) -> SUV-D | D2: =_xlfn.CONCAT(A2," ",B2) -> BLAZER RS AT | E2: 12. BLAZER | F2: RS 3.6 AT
A3: BLAZER EV | B3: RS AT | C3: =_xlfn.XLOOKUP(A3,SEGMENT!A:A,SEGMENT!B:B) -> SUV-D | D3: =_xlfn.CONCAT(A3," ",B3) -> BLAZER EV RS AT | E3: 13. BLAZER EV | F3: BLAZER EV
A4: BOLT EUV | B4: LT AT | C4: =_xlfn.XLOOKUP(A4,SEGMENT!A:A,SEGMENT!B:B) -> SUV-B | D4: =_xlfn.CONCAT(A4," ",B4) -> BOLT EUV LT AT | E4: 08. BOLT | F4: EUV
A5: BOLT EUV | B5: LT AT | C5: =_xlfn.XLOOKUP(A5,SEGMENT!A:A,SEGMENT!B:B) -> SUV-B | D5: =_xlfn.CONCAT(A5," ",B5) -> BOLT EUV LT AT | E5: 26. BOLT | F5: EUV
A6: CADILLAC | B6: CADILLAC | C6: =_xlfn.XLOOKUP(A6,SEGMENT!A:A,SEGMENT!B:B) -> CADILLAC | D6: =_xlfn.CONCAT(A6," ",B6) -> CADILLAC CADILLAC | E6: 23. CADILLAC | F6: CADILLAC
A7: CAMARO | B7: SS AT | C7: =_xlfn.XLOOKUP(A7,SEGMENT!A:A,SEGMENT!B:B) -> SPORT | D7: =_xlfn.CONCAT(A7," ",B7) -> CAMARO SS AT | E7: 16. CAMARO | F7: SS
A8: CAMARO | B8: ZL1 | C8: =_xlfn.XLOOKUP(A8,SEGMENT!A:A,SEGMENT!B:B) -> SPORT | D8: =_xlfn.CONCAT(A8," ",B8) -> CAMARO ZL1 | E8: 16. CAMARO | F8: ZL1
A9: CAPTIVA | B9: LT AT | C9: =_xlfn.XLOOKUP(A9,SEGMENT!A:A,SEGMENT!B:B) -> SUV-C | D9: =_xlfn.CONCAT(A9," ",B9) -> CAPTIVA LT AT | E9: 08. CAPTIVA TURBO | F9: LT CVT 5P
A10: CAPTIVA NEV | B10: EUV | C10: =_xlfn.XLOOKUP(A10,SEGMENT!A:A,SEGMENT!B:B) -> SUV-C | D10: =_xlfn.CONCAT(A10," ",B10) -> CAPTIVA NEV EUV | E10: 09. CAPTIVA EV | F10: F510S (EV)
A11: CAPTIVA NEV | B11: PHEV | C11: =_xlfn.XLOOKUP(A11,SEGMENT!A:A,SEGMENT!B:B) -> SUV-C | D11: =_xlfn.CONCAT(A11," ",B11) -> CAPTIVA NEV PHEV | E11: 09. CAPTIVA PHEV | F11: F510S (EV)
A12: CAPTIVA | B12: PREMIER AT | C12: =_xlfn.XLOOKUP(A12,SEGMENT!A:A,SEGMENT!B:B) -> SUV-C | D12: =_xlfn.CONCAT(A12," ",B12) -> CAPTIVA PREMIER AT | E12: 08. CAPTIVA TURBO | F12: PREMIER CVT 7P
A13: COLORADO | B13: OBSOLETO | C13: =_xlfn.XLOOKUP(A13,SEGMENT!A:A,SEGMENT!B:B) -> PICKUP-D | D13: =_xlfn.CONCAT(A13," ",B13) -> COLORADO OBSOLETO | E13: 18. COLORADO | F13: Drops/Old Versions
... A21: JOY | B21: BLACK MT | C21: =_xlfn.XLOOKUP(A21,SEGMENT!A:A,SEGMENT!B:B) -> CAR-B | D21: =_xlfn.CONCAT(A21," ",B21) -> JOY BLACK MT | E21: 02. JOY HB | F21: LT (BLACK)
A22: JOY NB | B22: BASE | C22: =_xlfn.XLOOKUP(A22,SEGMENT!A:A,SEGMENT!B:B) -> CAR-B | D22: =_xlfn.CONCAT(A22," ",B22) -> JOY NB BASE | E22: 01. JOY NB | F22: BASE | G22: JOY NB
A23: JOY NB | B23: BLACK MT | C23: =_xlfn.XLOOKUP(A23,SEGMENT!A:A,SEGMENT!B:B) -> CAR-B | D23: =_xlfn.CONCAT(A23," ",B23) -> JOY NB BLACK MT | E23: 01. JOY NB | F23: LT (BLACK)
A24: MONTANA | B24: OBSOLETO | C24: =_xlfn.XLOOKUP(A24,SEGMENT!A:A,SEGMENT!B:B) -> PICKUP-C | D24: =_xlfn.CONCAT(A24," ",B24) -> MONTANA OBSOLETO | E24: 17. MONTANA | F24: Drops/Old Versions
A25: MONTANA | B25: LTZ AT | C25: =_xlfn.XLOOKUP(A25,SEGMENT!A:A,SEGMENT!B:B) -> PICKUP-C | D25: =_xlfn.CONCAT(A25," ",B25) -> MONTANA LTZ AT | E25: 17. MONTANA | F25: LTZ
A26: MONTANA | B26: PREMIER AT | C26: =_xlfn.XLOOKUP(A26,SEGMENT!A:A,SEGMENT!B:B) -> PICKUP-C | D26: =_xlfn.CONCAT(A26," ",B26) -> MONTANA PREMIER AT | E26: 17. MONTANA | F26: PREMIER
A27: MONTANA | B27: RS AT | C27: =_xlfn.XLOOKUP(A27,SEGMENT!A:A,SEGMENT!B:B) -> PICKUP-C | D27: =_xlfn.CONCAT(A27," ",B27) -> MONTANA RS AT | E27: 17. MONTANA | F27: RS
A28: N400 | B28: CARGO | C28: =_xlfn.XLOOKUP(A28,SEGMENT!A:A,SEGMENT!B:B) -> VAN-B | D28: =_xlfn.CONCAT(A28," ",B28) -> N400 CARGO | E28: 21. N400 | F28: CARGO FULL
A29: N400 | B29: PASS | C29: =_xlfn.XLOOKUP(A29,SEGMENT!A:A,SEGMENT!B:B) -> VAN-B | D29: =_xlfn.CONCAT(A29," ",B29) -> N400 PASS | E29: 21. N400 | F29: PASAJEROS FULL
A30: ONIX | B30: OBSOLETO | C30: =_xlfn.XLOOKUP(A30,SEGMENT!A:A,SEGMENT!B:B) -> CAR-B | D30: =_xlfn.CONCAT(A30," ",B30) -> ONIX OBSOLETO | E30: 04. ONIX TURBO HB | F30: Drops/Old Versions
A31: ONIX | B31: RS MT | C31: =_xlfn.XLOOKUP(A31,SEGMENT!A:A,SEGMENT!B:B) -> CAR-B | D31: =_xlfn.CONCAT(A31," ",B31) -> ONIX RS MT | E31: 04. ONIX TURBO HB | F31: RS MT
A32: ONIX | B32: RS AT | C32: =_xlfn.XLOOKUP(A32,SEGMENT!A:A,SEGMENT!B:B) -> CAR-B | D32: =_xlfn.CONCAT(A32," ",B32) -> ONIX RS AT | E32: 04. ONIX TURBO HB | F32: RS AT
A33: ONIX | B33: PREMIER AT | C33: =_xlfn.XLOOKUP(A33,SEGMENT!A:A,SEGMENT!B:B) -> CAR-B | D33: =_xlfn.CONCAT(A33," ",B33) -> ONIX PREMIER AT | E33: 04. ONIX TURBO HB | F33: PREMIER AT
A34: ONIX NB | B34: LT MT | C34: =_xlfn.XLOOKUP(A34,SEGMENT!A:A,SEGMENT!B:B) -> CAR-B | D34: =_xlfn.CONCAT(A34," ",B34) -> ONIX NB LT MT | E34: 03. ONIX TURBO NB | F34: LT MT
... A50: SPIN | B50: LTZ AT | C50: =_xlfn.XLOOKUP(A50,SEGMENT!A:A,SEGMENT!B:B) -> MPV-B | D50: =_xlfn.CONCAT(A50," ",B50) -> SPIN LTZ AT | E50: 20. SPIN | F50: LTZ AT
A51: TAHOE | B51: Z71 AT | C51: =_xlfn.XLOOKUP(A51,SEGMENT!A:A,SEGMENT!B:B) -> SUV-E | D51: =_xlfn.CONCAT(A51," ",B51) -> TAHOE Z71 AT | E51: 15. TAHOE | F51: 5.3 LT 4X4 | G51: 5.3 Z71 4X4
A52: TAXI | B52: TAXI | C52: =_xlfn.XLOOKUP(A52,SEGMENT!A:A,SEGMENT!B:B) -> OTROS | D52: =_xlfn.CONCAT(A52," ",B52) -> TAXI TAXI | E52: 22. TAXI | F52: JOY
A53: TRACKER | B53: LS MT | C53: =_xlfn.XLOOKUP(A53,SEGMENT!A:A,SEGMENT!B:B) -> SUV-B | D53: =_xlfn.CONCAT(A53," ",B53) -> TRACKER LS MT | E53: 07. TRACKER TURBO | F53: LS MT
A54: TRACKER | B54: LS AT | C54: =_xlfn.XLOOKUP(A54,SEGMENT!A:A,SEGMENT!B:B) -> SUV-B | D54: =_xlfn.CONCAT(A54," ",B54) -> TRACKER LS AT | E54: 07. TRACKER TURBO | F54: LS AT
A55: TRACKER | B55: LTZ AT | C55: =_xlfn.XLOOKUP(A55,SEGMENT!A:A,SEGMENT!B:B) -> SUV-B | D55: =_xlfn.CONCAT(A55," ",B55) -> TRACKER LTZ AT | E55: 07. TRACKER TURBO | F55: LTZ AT
A56: TRACKER | B56: PREMIER AT | C56: =_xlfn.XLOOKUP(A56,SEGMENT!A:A,SEGMENT!B:B) -> SUV-B | D56: =_xlfn.CONCAT(A56," ",B56) -> TRACKER PREMIER AT | E56: 07. TRACKER TURBO | F56: PREMIER AT
A57: TRACKER | B57: RS AT | C57: =_xlfn.XLOOKUP(A57,SEGMENT!A:A,SEGMENT!B:B) -> SUV-B | D57: =_xlfn.CONCAT(A57," ",B57) -> TRACKER RS AT | E57: 07. TRACKER TURBO | F57: RS
A58: TRACKER | B58: LS MT | C58: =_xlfn.XLOOKUP(A58,SEGMENT!A:A,SEGMENT!B:B) -> SUV-B | D58: =_xlfn.CONCAT(A58," ",B58) -> TRACKER LS MT | E58: 07. TRACKER TURBO | F58: LS MT (D)-MCM
A59: TRACKER | B59: LS AT | C59: =_xlfn.XLOOKUP(A59,SEGMENT!A:A,SEGMENT!B:B) -> SUV-B | D59: =_xlfn.CONCAT(A59," ",B59) -> TRACKER LS AT | E59: 07. TRACKER TURBO | F59: LS AT (D)-MCM | G59: LT AT MCM
A60: TRACKER | B60: LTZ AT | C60: =_xlfn.XLOOKUP(A60,SEGMENT!A:A,SEGMENT!B:B) -> SUV-B | D60: =_xlfn.CONCAT(A60," ",B60) -> TRACKER LTZ AT | E60: 07. TRACKER TURBO | F60: LTZ AT (D)-MCM
A61: TRACKER | B61: PREMIER AT | C61: =_xlfn.XLOOKUP(A61,SEGMENT!A:A,SEGMENT!B:B) -> SUV-B | D61: =_xlfn.CONCAT(A61," ",B61) -> TRACKER PREMIER AT | E61: 07. TRACKER TURBO | F61: PREMIER AT (D)-MCM
A62: TRACKER | B62: RS AT | C62: =_xlfn.XLOOKUP(A62,SEGMENT!A:A,SEGMENT!B:B) -> SUV-B | D62: =_xlfn.CONCAT(A62," ",B62) -> TRACKER RS AT | E62: 07. TRACKER TURBO | F62: RS-MCM
...

Sheet BOLIVIA
A1: NAMEPLATE | B1: TRIM | C1: SEGMENT | D1: CONCAT | E1: NAMEPLATE COUNTRY | F1: TRIM 1 | G1: TRIM 2 | H1: TRIM 3
A2: BEAT | B2: OBSOLETO | C2: =_xlfn.XLOOKUP(A2,SEGMENT!A:A,SEGMENT!B:B) -> CAR-A | D2: =_xlfn.CONCAT(A2," ",B2) -> BEAT OBSOLETO | E2: BEAT 1.2 PREMIER MT | F2: NO
A3: BLAZER | B3: OBSOLETO | C3: =_xlfn.XLOOKUP(A3,SEGMENT!A:A,SEGMENT!B:B) -> SUV-D | D3: =_xlfn.CONCAT(A3," ",B3) -> BLAZER OBSOLETO | E3: BLAZER RS 3.6L AWD AT | F3: NO
A4: CAMARO | B4: OBSOLETO | C4: =_xlfn.XLOOKUP(A4,SEGMENT!A:A,SEGMENT!B:B) -> SPORT | D4: =_xlfn.CONCAT(A4," ",B4) -> CAMARO OBSOLETO | E4: CAMARO COUPÉ 6.2 V8 SS AT | F4: NO
A5: CAPTIVA | B5: OBSOLETO | C5: =_xlfn.XLOOKUP(A5,SEGMENT!A:A,SEGMENT!B:B) -> SUV-C | D5: =_xlfn.CONCAT(A5," ",B5) -> CAPTIVA OBSOLETO | E5: NEW CAPTIVA 1.5T LTZ MT | F5: NO
A6: CAPTIVA | B6: OBSOLETO | C6: =_xlfn.XLOOKUP(A6,SEGMENT!A:A,SEGMENT!B:B) -> SUV-C | D6: =_xlfn.CONCAT(A6," ",B6) -> CAPTIVA OBSOLETO | E6: NEW CAPTIVA 1.5T LTZ AT | F6: NO
A7: CAPTIVA | B7: OBSOLETO | C7: =_xlfn.XLOOKUP(A7,SEGMENT!A:A,SEGMENT!B:B) -> SUV-C | D7: =_xlfn.CONCAT(A7," ",B7) -> CAPTIVA OBSOLETO | E7: NEW CAPTIVA 1.5T PREMIER MT | F7: NO
A8: CAPTIVA | B8: OBSOLETO | C8: =_xlfn.XLOOKUP(A8,SEGMENT!A:A,SEGMENT!B:B) -> SUV-C | D8: =_xlfn.CONCAT(A8," ",B8) -> CAPTIVA OBSOLETO | E8: NEW CAPTIVA 1.5T PREMIER AT | F8: NO
A9: CAPTIVA NEV | B9: PHEV | C9: =_xlfn.XLOOKUP(A9,SEGMENT!A:A,SEGMENT!B:B) -> SUV-C | D9: =_xlfn.CONCAT(A9," ",B9) -> CAPTIVA NEV PHEV | E9: CAPTIVA PHEV | F9: SI
A10: CAPTIVA NEV | B10: EV | C10: =_xlfn.XLOOKUP(A10,SEGMENT!A:A,SEGMENT!B:B) -> SUV-C | D10: =_xlfn.CONCAT(A10," ",B10) -> CAPTIVA NEV EV | E10: CAPTIVA EV | F10: SI
A11: GROOVE | B11: RS MT | C11: =_xlfn.XLOOKUP(A11,SEGMENT!A:A,SEGMENT!B:B) -> SUV-B | D11: =_xlfn.CONCAT(A11," ",B11) -> GROOVE RS MT | E11: GROOVE RS MT | F11: SI
A12: GROOVE | B12: RS CVT | C12: =_xlfn.XLOOKUP(A12,SEGMENT!A:A,SEGMENT!B:B) -> SUV-B | D12: =_xlfn.CONCAT(A12," ",B12) -> GROOVE RS CVT | E12: GROOVE RS CVT | F12: SI
A13: GROOVE | B13: RS MT | C13: =_xlfn.XLOOKUP(A13,SEGMENT!A:A,SEGMENT!B:B) -> SUV-B | D13: =_xlfn.CONCAT(A13," ",B13) -> GROOVE RS MT | E13: GROOVE 1.5 RS MT | F13: SI
... A66: TRAVERSE | B66: Z71 AT | C66: =_xlfn.XLOOKUP(A66,SEGMENT!A:A,SEGMENT!B:B) -> SUV-D | D66: =_xlfn.CONCAT(A66," ",B66) -> TRAVERSE Z71 AT | E66: NEW TRAVERSE Z71 | F66: SI
